Traceback (most recent call last):
  File "/home/bake/Rest-to-Rest/.venv/lib/python3.10/site-packages/sqlalchemy/engine/base.py", line 1963, in _exec_single_context
    self.dialect.do_execute(
  File "/home/bake/Rest-to-Rest/.venv/lib/python3.10/site-packages/sqlalchemy/engine/default.py", line 943, in do_execute
    cursor.execute(statement, parameters)
sqlite3.OperationalError: table studies already exists

The above exception was the direct cause of the following exception:

Traceback (most recent call last):
  File "/home/bake/Rest-to-Rest/scripts/ConvNet/train_optuna_manager.py", line 97, in <module>
    study = optuna.create_study(
  File "/home/bake/Rest-to-Rest/.venv/lib/python3.10/site-packages/optuna/_convert_positional_args.py", line 135, in converter_wrapper
    return func(**kwargs)  # type: ignore[call-arg]
  File "/home/bake/Rest-to-Rest/.venv/lib/python3.10/site-packages/optuna/study/study.py", line 1295, in create_study
    storage = storages.get_storage(storage)
  File "/home/bake/Rest-to-Rest/.venv/lib/python3.10/site-packages/optuna/storages/__init__.py", line 49, in get_storage
    return _CachedStorage(RDBStorage(storage))
  File "/home/bake/Rest-to-Rest/.venv/lib/python3.10/site-packages/optuna/storages/_rdb/storage.py", line 238, in __init__
    models.BaseModel.metadata.create_all(self.engine)
  File "/home/bake/Rest-to-Rest/.venv/lib/python3.10/site-packages/sqlalchemy/sql/schema.py", line 5924, in create_all
    bind._run_ddl_visitor(
  File "/home/bake/Rest-to-Rest/.venv/lib/python3.10/site-packages/sqlalchemy/engine/base.py", line 3248, in _run_ddl_visitor
    conn._run_ddl_visitor(visitorcallable, element, **kwargs)
  File "/home/bake/Rest-to-Rest/.venv/lib/python3.10/site-packages/sqlalchemy/engine/base.py", line 2455, in _run_ddl_visitor
    ).traverse_single(element)
  File "/home/bake/Rest-to-Rest/.venv/lib/python3.10/site-packages/sqlalchemy/sql/visitors.py", line 664, in traverse_single
    return meth(obj, **kw)
  File "/home/bake/Rest-to-Rest/.venv/lib/python3.10/site-packages/sqlalchemy/sql/ddl.py", line 982, in visit_metadata
    self.traverse_single(
  File "/home/bake/Rest-to-Rest/.venv/lib/python3.10/site-packages/sqlalchemy/sql/visitors.py", line 664, in traverse_single
    return meth(obj, **kw)
  File "/home/bake/Rest-to-Rest/.venv/lib/python3.10/site-packages/sqlalchemy/sql/ddl.py", line 1020, in visit_table
    )._invoke_with(self.connection)
  File "/home/bake/Rest-to-Rest/.venv/lib/python3.10/site-packages/sqlalchemy/sql/ddl.py", line 321, in _invoke_with
    return bind.execute(self)
  File "/home/bake/Rest-to-Rest/.venv/lib/python3.10/site-packages/sqlalchemy/engine/base.py", line 1415, in execute
    return meth(
  File "/home/bake/Rest-to-Rest/.venv/lib/python3.10/site-packages/sqlalchemy/sql/ddl.py", line 187, in _execute_on_connection
    return connection._execute_ddl(
  File "/home/bake/Rest-to-Rest/.venv/lib/python3.10/site-packages/sqlalchemy/engine/base.py", line 1526, in _execute_ddl
    ret = self._execute_context(
  File "/home/bake/Rest-to-Rest/.venv/lib/python3.10/site-packages/sqlalchemy/engine/base.py", line 1842, in _execute_context
    return self._exec_single_context(
  File "/home/bake/Rest-to-Rest/.venv/lib/python3.10/site-packages/sqlalchemy/engine/base.py", line 1982, in _exec_single_context
    self._handle_dbapi_exception(
  File "/home/bake/Rest-to-Rest/.venv/lib/python3.10/site-packages/sqlalchemy/engine/base.py", line 2351, in _handle_dbapi_exception
    raise sqlalchemy_exception.with_traceback(exc_info[2]) from e
  File "/home/bake/Rest-to-Rest/.venv/lib/python3.10/site-packages/sqlalchemy/engine/base.py", line 1963, in _exec_single_context
    self.dialect.do_execute(
  File "/home/bake/Rest-to-Rest/.venv/lib/python3.10/site-packages/sqlalchemy/engine/default.py", line 943, in do_execute
    cursor.execute(statement, parameters)
sqlalchemy.exc.OperationalError: (sqlite3.OperationalError) table studies already exists
[SQL: 
CREATE TABLE studies (
	study_id INTEGER NOT NULL, 
	study_name VARCHAR(512) NOT NULL, 
	PRIMARY KEY (study_id)
)

]
(Background on this error at: https://sqlalche.me/e/20/e3q8)
slurmstepd-s_004_m: error: common_file_write_uints: write value '4082676' to '/sys/fs/cgroup/cgroup.procs' failed: Device or resource busy
slurmstepd-s_004_m: error: Unable to move pid 4082676 to init root cgroup /sys/fs/cgroup
